Workbook

Sheet day schedule
A2: Day 1
A3: langold tuxford retford | B3: =langold!B29 -> 434
A5: Day 2
A6: model view | B6: ='Model way'!B43 -> 305
A8: Day 3
A9: rogers and portland | B9: =RogersPortland!B49 -> 440
A11: Day 3
A12: West st, sherwood, eyre, skinner | B12: =Creswell!B39 -> 317
A14: Day 4
A15: elmton rd frithwood | B15: ='Elmton rd'!B43 -> 483
A17: Day 5
A18: bolsover, clowne, langwith | B18: ='Bolsover and Clowne'!B28 -> 346
A20: Day 6
A21: Perlthorpe, edwinstowe, cuckney | B21: =edwinstowe!B20 -> 232
A23: Day 7
A24: Welbeck | B24: ='welbeck and norton'!B36 -> 450
A26: Day 8
A27: carlton rd, rhodesia | B27: ='welbeck and norton'!B36 -> 450
A29: Day 9
A30: gateford, thievesdale | B30: ='Rhodesiacarlton rd'!B50 -> 513
B34: =sum(B3:B30) -> 3970
A36: after price rise proposed
B37: =sum(langold!Q29,'Model way'!Q43,RogersPortland!Q49,Creswell!Q33,'Elmton rd'!Q43,'Bolsover and Clowne'!Q29,edwinstowe!Q20,'welbeck and norton'!Q36,'Rhodesiacarlton rd'!Q51,gatefordhemmingfield!Q50) -> 4394

Sheet langold
Q1: new prices (proposed)
A2: Address | B2: Cost | C2: Frequency | D2: 45650 | E2: Jan | F2: Feb | G2: Mar | H2: Apr | I2: May | J2: Jun | K2: Jul | L2: Aug | M2: Sep | N2: Oct | O2: Nov | P2: Dec
A3: 68 riddel | B3: 20 | C3: 4 weeks | D3: owing | E3: skipped | Q3: 20
A4: 15 markham langold | B4: 15 | C4: 4 weeks | D4: paid | E4: paid | Q4: 17
A5: 6 cross street | B5: 11 | C5: 4 weeks | D5: skipped | E5: owing | Q5: 12
A6: 31 church st langold | B6: 14 | C6: 4 weeks | D6: paid | E6: paid | Q6: 15
A7: 33 church st langold | B7: 12 | C7: 4 weeks | D7: paid | E7: paid | Q7: 12
A8: 12 church st langold | B8: 10 | C8: 4 weeks | D8: paid | E8: paid | Q8: 12
A9: 7 main st oldcotes | B9: 17 | C9: 4 weeks | D9: paid | E9: paid | Q9: 19
A10: roche house oldcotes | B10: 20 | C10: 8 weeks | D10: paid | E10: skipped | Q10: 22
A11: gildingwells farm | B11: 40 | C11: 4 weeks | D11: paid | E11: skipped | Q11: 45
A12: 86 lincoln rd tuxford | B12: 14 | C12: 4 weeks | D12: paid | E12: paid | Q12: 16
A13: 14b gilbert ave tuxford | B13: 10 | C13: 4 weeks | D13: paid | E13: paid | Q13: 10
A14: 15 machin tuxford | B14: 15 | C14: 4 weeks | D14: paid | E14: paid | Q14: 17
... A26: White cottage budby | B26: 30 | C26: 8 weeks | D26: paid | E26: skipped | Q26: 30
B29: =sum(B3:B26) -> 434 | Q29: =SUM(Q3:Q26) -> 458

Sheet Model way
A2: Address | B2: Cost | C2: Frequency | D2: 45650 | E2: Jan | F2: Feb | G2: Mar | H2: Apr | I2: May | J2: Jun | K2: Jul | L2: Aug | M2: Sep | N2: Oct | O2: Nov | P2: Dec | Q2: new prices (proposed)
A3: Creswell - Model Lane
A4: 2 | B4: 8 | C4: 4 | D4: paid | E4: skipped | H4: owing | Q4: 10
A5: 3 | B5: 10 | C5: 4 | D5: paid | E5: fronts | H5: owing | Q5: 10
A6: 4 | B6: 8 | C6: 4 | D6: paid | E6: paid | H6: paid | Q6: 10
A7: 10 | B7: 12 | C7: 4 | D7: paid | E7: skipped | H7: skipped | Q7: 12
A8: 11 | B8: 8 | C8: 4 | D8: paid | E8: paid | H8: paid | Q8: 10
A9: 16 | B9: 12 | C9: 4 | D9: paid | E9: paid | H9: paid | Q9: 12
A10: 18 | B10: 8 | C10: 4 | D10: owing | E10: skipped | H10: owing | Q10: 10
A11: 17 | B11: 10 | C11: 4 | D11: paid | E11: paid | H11: paid | Q11: 12
A12: 31 | B12: 17 | C12: 4 | D12: paid | E12: paid | H12: skipped | Q12: 17
A13: 33 | B13: 8 | C13: 4 | D13: paid | E13: skipped | H13: skipped | Q13: 10
A14: Creswell - Model View
A15: 8 | B15: 8 | C15: 4 | D15: owing | E15: owing | Q15: 10
A16: 10 | B16: 8 | C16: 4 | D16: paid | E16: paid | Q16: 10
A17: 14 | B17: 8 | C17: 4 | D17: paid | E17: owing | Q17: 10
A18: Creswell - Fox Street
A19: 10 | B19: 8 | C19: 4 | D19: paid | E19: owing | Q19: 10
A20: 27 | B20: 8 | C20: 4 | D20: paid | E20: paid | Q20: 10
A21: 44 | B21: 8 | C21: 4 | D21: paid | E21: paid | Q21: 10
A22: 17 | B22: 12 | C22: 4 | D22: paid | E22: paid | Q22: 12
A23: 14 | B23: 12 | C23: 4 | D23: paid | E23: paid | Q23: 12
A24: 34 | B24: 12 | C24: 4 | D24: paid | E24: paid | Q24: 12
A25: Fox Lane
A26: 1 | B26: 8 | C26: 4 | D26: paid | E26: paid | F26: skipped | Q26: 10
A27: 3 | B27: 8 | C27: 4 | D27: paid | E27: paid | Q27: 10
A29: Creswell - Colliery Street
A30: 2 | B30: 10 | C30: 4 | D30: paid | E30: fronts | Q30: 12
A31: 6 | B31: 12 | C31: 4 | D31: paid | E31: paid | Q31: 12
A32: 12 | B32: 10 | C32: 4 | D32: paid | E32: paid | Q32: 12
A33: 26 | B33: 12 | C33: 4 | D33: paid | E33: paid | Q33: 12
A34: colliery way
A35: 2 | B35: 12 | C35: 4 | D35: paid | E35: paid | Q35: 12
A36: 4 | B36: 12 | C36: 4 | D36: paid | E36: paid | Q36: 12
A37: elmton way
A38: 15 | B38: 12 | C38: 8 | D38: paid | E38: skipped | Q38: 12
A39: 7 | B39: 12 | C39: 4 | D39: paid | E39: owing | Q39: 12
A40: 4 | B40: 12 | C40: 8 | D40: paid | E40: skipped | Q40: 12
B43: =sum(B4:B40) -> 305 | Q43: =sum(Q4:Q40) -> 337

Sheet RogersPortland
A1: Address | B1: Cost | C1: Frequency | D1: 45650 | E1: Jan | F1: Feb | G1: Mar | H1: Apr | I1: May | J1: Jun | K1: Jul | L1: Aug | M1: Sep | N1: Oct | O1: Nov | P1: Dec | Q1: new prices (proposed)
A2: 1 Rogers AVE | B2: 12 | C2: 4 weeks | D2: paid | E2: fronts | Q2: 12
A3: 3 Rogers ave | B3: 12 | C3: 4 weeks | D3: paid | E3: owing | Q3: 12
A4: 5 Rogers AVE | B4: 8 | C4: 4 weeks | D4: paid | E4: paid | Q4: 8
A5: 9 Rogers AVE | B5: 5 | C5: 4 weeks | D5: paid | E5: paid | Q5: 5
A6: 11 Rogers AVE | B6: 10 | C6: 4 weeks | D6: paid | E6: paid | Q6: 10
A7: 13 Rogers AVE | B7: 10 | C7: 4 weeks | D7: paid | E7: paid | Q7: 10
A8: 15 Rogers AVE | B8: 10 | C8: 4 weeks | D8: owing | E8: skipped | Q8: 10
A9: 17 Rogers AVE | B9: 10 | C9: 4 weeks | D9: paid | E9: paid | Q9: 10
A10: 19 Rogers AVE | B10: 10 | C10: 4 weeks | D10: paid | E10: paid | Q10: 10
A11: 21 Rogers AVE | B11: 12 | C11: 4 weeks | D11: paid | E11: paid | Q11: 12
A12: 25 Rogers AVE | B12: 10 | C12: 4 weeks | D12: paid | E12: owing | Q12: 10
A13: 29 Rogers AVE | B13: 10 | C13: 4 weeks | D13: paid | E13: owing | Q13: 10
... A16: 37 Rogers 10 | B16: 10 | C16: 4 weeks | D16: paid | E16: paid | Q16: 10
A17: 39 Rogers AVE | B17: 7 | C17: 4 weeks | D17: paid | Q17: 7
A18: 2 Rogers AVE | B18: 12 | C18: 4 weeks | D18: paid | E18: paid | Q18: 12
A19: 6 Rogers AVE | B19: 12 | C19: 4 weeks | D19: paid | E19: owing | Q19: 12
A20: 14 Rogers AVE | B20: 10 | C20: 4 weeks | D20: paid | E20: paid | Q20: 10
A21: 18 Rogers AVE | B21: 10 | C21: 4 weeks | D21: paid | E21: paid | Q21: 10
A22: 20 Rogers AVE | B22: 10 | C22: 4 weeks | D22: paid | E22: paid | Q22: 10
A23: 24 rogers | B23: 12 | C23: 4 weeks | D23: paid | E23: owing
A24: 26 Rogers AVE | B24: 10 | C24: 4 weeks | D24: paid | E24: paid | Q24: 10
A25: 28 Rogers AVE | B25: 10 | C25: 4 weeks | D25: paid | E25: paid | Q25: 10
A26: 30 Rogers AVE | B26: 10 | C26: 4 weeks | D26: paid | E26: owing | Q26: 10
A27: 32 Rogers AVE | B27: 10 | C27: 4 weeks | D27: paid | E27: paid | Q27: 10
A28: 34 Rogers AVE | B28: 12 | C28: 4 weeks | D28: paid | E28: paid | Q28: 12
A29: 42a Rogers AVE | B29: 5 | C29: 4 weeks | D29: paid | E29: owing | Q29: 5
A30: 40 portland | B30: 10 | C30: 4 weeks | D30: paid | E30: paid | Q30: 10
A31: 48 Portland | B31: 10 | C31: 4 weeks | D31: paid | E31: paid | F31: paid | G31: paid | H31: paid | I31: paid | Q31: 10
A32: 50 portland | B32: 10 | C32: 4 weeks | D32: paid | E32: paid | Q32: 10
A33: 54 portland ave | B33: 7 | C33: 4 weeks | D33: paid | E33: paid | Q33: 7
A34: 66 portland | B34: 10 | C34: 8 weeks | D34: paid | E34: paid | Q34: 10
A35: 70 portland | B35: 10 | C35: 4 weeks | D35: paid | E35: owing | Q35: 10
A36: 74 portland | B36: 10 | C36: 4 weeks | D36: paid | E36: paid | Q36: 10
A37: 76 portland | B37: 12 | C37: 4 weeks | D37: paid | E37: owing | Q37: 12
A38: 82 portland | B38: 10 | C38: 4 weeks | D38: paid | E38: paid | Q38: 10
A39: 84 portland | B39: 10 | C39: 4 weeks | D39: paid | E39: paid | Q39: 10
A40: 39 portland | B40: 10 | C40: 4 weeks | D40: paid | E40: paid | Q40: 10
A41: 41 portland | B41: 10 | C41: 4 weeks | D41: paid | E41: paid | Q41: 10
A42: 55 portland | B42: 10 | C42: 4 weeks | D42: paid | E42: owing | Q42: 10
...

Sheet Creswell
A1: Address | B1: Cost | C1: Frequency | D1: 45650 | E1: Jan | F1: Feb | G1: Mar | H1: Apr | I1: May | J1: Jun | K1: Jul | L1: Aug | M1: Sep | N1: Oct | O1: Nov | P1: Dec | Q1: new prices (proposed)
A2: 5 Sherwood AVE | B2: 5 | C2: 4 weeks | D2: paid | E2: paid | Q2: 6
A3: 7 Sherwood AVE | B3: 7 | C3: 4 weeks | D3: paid | E3: paid | Q3: 8
A4: 15 Sherwood AVE | B4: 10 | C4: 4 weeks | D4: paid | E4: paid | Q4: 12
A5: 2 Sherwood AVE | B5: 10 | C5: 8 weeks | D5: paid | E5: paid | Q5: 14
A6: 6 Sherwood AVE | B6: 10 | C6: 4 weeks | D6: paid | E6: paid | Q6: 12
A7: 16 Sherwood AVE | B7: 10 | C7: 4 weeks | D7: paid | E7: paid | Q7: 12
A8: 28 Sherwood AVE | B8: 11 | C8: 4 weeks | D8: paid | E8: paid | Q8: 12
A9: 30 Sherwood AVE | B9: 10 | C9: 4 weeks | D9: paid | E9: paid | Q9: 12
A10: 34 Sherwood AVE | B10: 7 | C10: 4 weeks | D10: paid | E10: paid | Q10: 7
A11: 36 Sherwood AVE | B11: 12 | C11: 4 weeks | D11: paid | E11: fronts | Q11: 12
A12: 4 west st | B12: 10 | C12: 4 weeks | D12: paid | E12: paid | Q12: 12
A13: 6 west st | B13: 5 | C13: 4 weeks | D13: paid | E13: paid | Q13: 6
... A31: 77 skinner st | B31: 10 | C31: 4 weeks | D31: paid | E31: paid | Q31: 12
Q33: =SUM(Q2:Q31) -> 365
B39: =sum(B2:B31) -> 317

Sheet Elmton rd
A1: Address | B1: Cost | C1: Frequency | D1: 45650 | E1: Jan | F1: Feb | G1: Mar | H1: Apr | I1: May | J1: Jun | K1: Jul | L1: Aug | M1: Sep | N1: Oct | O1: Nov | P1: Dec | Q1: new prices (proposed)
A2: 4 Cavendish | B2: 15 | C2: 4 weeks | D2: paid | E2: paid | Q2: 17
A3: 11 Devonshire drive | B3: 10 | C3: 4 weeks | D3: paid | E3: paid | Q3: 12
A4: 10 Devonshire drive | B4: 8 | C4: 4 weeks | D4: paid | E4: paid | Q4: 10
A5: 8 Devonshire drive | B5: 10 | C5: 4 weeks | D5: paid | E5: paid | Q5: 12
A6: 10 beely close | B6: 13 | C6: 4 weeks | D6: paid | E6: paid | Q6: 15
A7: 21 elmton rd | B7: 10 | C7: 4 weeks | D7: paid | E7: paid | Q7: 12
A8: 23 elmton rd | B8: 10 | C8: 4 weeks | D8: paid | E8: fronts | Q8: 12
A9: 65a elmton rd bluebell bungalow | B9: 12 | C9: 4 weeks | D9: paid | E9: owing | Q9: 14
A10: 162 elmton rd | B10: 10 | C10: 4 weeks | D10: paid | E10: paid | Q10: 10
A11: 166 elmton rd | B11: 10 | C11: 4 weeks | D11: paid | E11: paid | Q11: 12
A12: 168 elmton rd | B12: 12 | C12: 8 weeks | D12: paid | E12: skipped | Q12: 14
A13: 170 elmton rd | B13: 10 | C13: 4 weeks | D13: paid | E13: paid | Q13: 12
... A41: mistal barn | B41: 20 | C41: 4 weeks | D41: paid | E41: owing | Q41: 22
B43: =sum(B2:B41) -> 483 | Q43: =SUM(Q2:Q42) -> 521

Sheet Bolsover and Clowne
A1: Address | B1: Cost | C1: Frequency | D1: 45650 | E1: Jan | F1: Feb | G1: Mar | H1: Apr | I1: May | J1: Jun | K1: Jul | L1: Aug | M1: Sep | N1: Oct | O1: Nov | P1: Dec | Q1: new prices (proposed)
A2: 1 Highfield | B2: 10 | C2: 4 weeks | D2: paid | Q2: 12
A3: 3 Highfield | B3: 15 | C3: 4 weeks | D3: paid | Q3: 15
A4: 5 Highfield | B4: 12 | C4: 4 weeks | D4: paid | Q4: 13
A5: 7 Highfield | B5: 17 | C5: 4 weeks | D5: paid | Q5: 18
A6: 9 Highfield | B6: 15 | C6: 4 weeks | D6: paid | Q6: 17
A7: 11 Highfield | B7: 12 | C7: 4 weeks | D7: paid | Q7: 13
A8: 15 Highfield | B8: 5 | C8: 4 weeks | D8: paid | Q8: 6
A9: 17 Highfield | B9: 5 | C9: 4 weeks | D9: paid | Q9: 6
A10: 6 Highfield | B10: 14 | C10: 4 weeks | D10: paid | Q10: 15
A11: 8 Highfield | B11: 15 | C11: 4 weeks | D11: paid | Q11: 15
A12: 14 brookfield | B12: 12 | C12: 4 weeks | D12: paid | Q12: 12
A13: 10 Brookfield | B13: 10 | C13: 4 weeks | D13: paid | Q13: 12
... A26: mark and rachels | B26: 15 | C26: 4 weeks | D26: paid | Q26: 15
B28: =sum(B4:B26) -> 346
Q29: =SUM(Q2:Q28) -> 396

Sheet edwinstowe
C1: Month______________________
A2: Address | B2: Cost | C2: Frequency | D2: 45650 | E2: Jan | F2: Feb | G2: Mar | H2: Apr | I2: May | J2: Jun | K2: Jul | L2: Aug | M2: Sep | N2: Oct | O2: Nov | P2: Dec | Q2: new prices (proposed)
A3: 25 beardsley rd edwinstowe | B3: 10 | C3: 12 weeks | D3: paid | E3: paid | Q3: 12
A4: 10 beardsley rd edwinstowe | B4: 7 | C4: 4 weeks | D4: paid | E4: paid | Q4: 8
A5: 32 first ave edwinstowe | B5: 10 | C5: 4 weeks | D5: paid | E5: owing | Q5: 12
A6: 49 first ave edwinstowe | B6: 17 | C6: 4 weeks | D6: paid | E6: owing | Q6: 17
A7: 92 fourth ave edwinstowe | B7: 10 | C7: 4 weeks | D7: paid | E7: owing | Q7: 12
A8: 56 fifth ave edwinstowe | B8: 13 | C8: 4 weeks | D8: paid | E8: owing | Q8: 15
A9: 54 fifth ave edwinstowe | B9: 10 | C9: 4 weeks | D9: paid | E9: owing | Q9: 12
A10: Andy knowles edwinstowe | B10: 30 | C10: 4 weeks | D10: paid | E10: paid | Q10: 35
A11: the kennels perlthorpe | B11: 25 | C11: 8 weeks | D11: skipped | E11: owing | Q11: 27
A12: 10 jackson hill | B12: 5 | C12: 4 weeks | D12: paid | E12: paid | Q12: 5
A13: 8 jackson hill perlthorpe | B13: 15 | C13: 4 weeks | D13: paid | E13: paid | Q13: 15
A14: 3 jackson hill perlthorpe | B14: 20 | C14: 4 weeks | D14: skipped | E14: paid | Q14: 20
... A18: middlehouse bothamsall | B18: 25 | C18: 8 weeks | D18: skipped | E18: owing | Q18: 25
B20: =SUM(B2:B18) -> 232 | Q20: =SUM(Q2:Q18) -> 250

Sheet welbeck and norton
A2: Address | B2: Cost | D2: 45650 | E2: Jan | F2: Feb | G2: Mar | H2: Apr | I2: May | J2: Jun | K2: Jul | L2: Aug | M2: Sep | N2: Oct | O2: Nov | P2: Dec | Q2: new prices (proposed)
A3: Meadow lodge welbeck | B3: 25 | C3: 8 weeks | D3: paid | Q3: 25
A4: 4 lake view | B4: 12 | C4: 4 weeks | D4: paid | Q4: 14
A5: 2 lake view | B5: 12 | C5: 4 weeks | D5: paid | Q5: 14
A6: 1 lake view | B6: 12 | C6: 4 weeks | D6: paid | Q6: 14
A7: meadowside bungalow (alan bellingham) | B7: 15 | C7: 4 weeks | D7: paid | Q7: 17
A8: mallards | B8: 18 | C8: 4 weeks | D8: skipped | Q8: 20
A9: mr brightman | B9: 19 | C9: 4 weeks | D9: owing | Q9: 20
A10: Walpole | B10: 25 | C10: 4weeks | D10: paid | Q10: 25
A11: tea rooms | B11: 25 | C11: 4 weeks | D11: skipped | Q11: 25
A12: bentink lodge | B12: 17 | C12: 4 weeks | D12: paid | Q12: 18
A13: 4 lady margaret cres | B13: 10 | C13: 4 weeks | D13: paid | Q13: 10
A14: 3 lady margaret cres | B14: 10 | C14: 4 weeks | D14: paid | Q14: 10
... A33: john and jayne | B33: 12 | C33: 4 weeks | D33: paid | Q33: 14
B36: =SUM(B3:B33) -> 450 | Q36: =SUM(Q3:Q33) -> 478

Sheet gatefordhemmingfield
A1: Address | B1: Cost | C1: Frequency | D1: 45650 | E1: Jan | F1: Feb | G1: Mar | H1: Apr | I1: May | J1: Jun | K1: Jul | L1: Aug | M1: Sep | N1: Oct | O1: Nov | P1: Dec | Q1: new prices (proposed)
A2: 2 hemmingfield cres | B2: 10 | C2: 4 weeks | D2: paid | Q2: 12
A3: 4 hemmingfield cres | B3: 12 | C3: 4 weeks | D3: paid | Q3: 12
A4: 6 hemmingfield cres | B4: 15 | C4: 8 weeks | D4: owing | Q4: 15
A5: 1 hemmingfield cres | B5: 12 | C5: 4 weeks | D5: paid | Q5: 14
A6: 3 hemmingfield cres | B6: 10 | C6: 4 weeks | D6: paid | Q6: 12
A7: 7 hemmingfield cres | B7: 15 | C7: 4 weeks | D7: fronts | Q7: 17
A8: 28 hemmingfield cres | B8: 10 | C8: 4 weeks | D8: paid | Q8: 12
A9: 1 hemmingfield way | B9: 12 | C9: 4 weeks | D9: paid | Q9: 14
A10: 8 hemmingfield road | B10: 15 | C10: 4 weeks | D10: paid | Q10: 15
A11: 9 grasmere | B11: 8 | C11: 4 weeks | D11: paid | Q11: 10
A12: 8 grasmere | B12: 10 | C12: 4 weeks | D12: paid | Q12: 12
A13: 10 grasmere | B13: 15 | C13: 8 weeks | D13: skipped | Q13: 15
... A47: 2 belgravia ct | B47: 15 | C47: 4 weeks | D47: paid | Q47: 15
B50: =SUM(B2:B46) -> 538 | Q50: =SUM(Q2:Q47) -> 610

Sheet Rhodesiacarlton rd
A1: Address | B1: Cost | C1: Frequency | D1: 45650 | E1: Jan | F1: Feb | G1: Mar | H1: Apr | I1: May | J1: Jun | K1: Jul | L1: Aug | M1: Sep | N1: Oct | O1: Nov | P1: Dec | Q1: new prices (proposed)
A2: 2 robertson grove rhodesia | B2: 10 | C2: 4 weeks | D2: paid | Q2: 12
A3: 2a robertson grove | B3: 10 | C3: 4 weeks | D3: owing | Q3: 10
A4: 4 Robertson grove Rhodesia | B4: 10 | C4: 4 weeks | D4: paid | Q4: 12
A5: 31 Robertson grove Rhodesia | B5: 10 | C5: 4 weeks | D5: paid | Q5: 10
A6: 32 Robertson grove Rhodesia | B6: 8 | C6: 4 weeks | D6: paid | Q6: 10
A7: 36 Robertson grove Rhodesia | B7: 8 | C7: 4 weeks | D7: paid | Q7: 10
A8: 37 Robertson grove Rhodesia | B8: 8 | C8: 4 weeks | D8: paid | Q8: 10
A9: 38 Robertson grove Rhodesia | B9: 10 | C9: 4 weeks | D9: paid | Q9: 10
A10: 39 Robertson grove Rhodesia | B10: 10 | C10: 4 weeks | D10: skipped | Q10: 10
A11: 40 robertson | B11: 10 | C11: 4 weeks | D11: paid | Q11: 10
A12: 41 Robertson grove Rhodesia | B12: 6 | C12: 4 weeks | D12: paid | Q12: 8
A13: 2 Goranson walk Rhodesia | B13: 6 | C13: 4 weeks | D13: paid | Q13: 8
... A48: 152 Newcastle ave | B48: 10 | C48: 4 weeks | D48: paid | Q48: 10
B50: =SUM(B2:B48) -> 513
Q51: =SUM(Q2:Q50) -> 551

Sheet dale close
A1: Address | B1: Cost | C1: Frequency | D1: 45650 | E1: Jan | F1: Feb | G1: Mar | H1: Apr | I1: May | J1: Jun | K1: Jul | L1: Aug | M1: Sep | N1: Oct | O1: Nov | P1: Dec
A2: 12 dale close | B2: 10 | C2: 4 weeks
A3: 14dale close | B3: 15 | C3: 4 weeks
A4: 18 dale close | B4: 10 | C4: 4 weeks
A5: 20 dale close | B5: 10 | C5: 4 weeks
A6: 13 dale close | B6: 10 | C6: 4 weeks
A7: 74 dale close | B7: 10 | C7: 4 weeks
A8: 76 dale close | B8: 10 | C8: 4 weeks
A9: 129 dale close | B9: 10 | C9: 4 weeks
A10: 132 dale close | B10: 10 | C10: 4 weeks
A11: 134 dale close | B11: 15 | C11: 4 weeks
A12: 140 dale close | B12: 10 | C12: 4 weeks
A13: 142 dale close | B13: 10 | C13: 4 weeks
... A20: 105 dale close | B20: 10 | C20: 4 weeks
C21: 4 weeks
A22: 69 woodlands | B22: 10 | C22: 4 weeks
A23: 72 woodlands | B23: 10 | C23: 4 weeks
B26: =sum(B2:B23) -> 220

Sheet notes 
A2: 1 Rogers AVE gutter inspection, clean and clear soffits fascias windows £100
A4: 17 cemetery
A7: 9 season £14 quote .
A11: Joanne Holme farm Holbeck £23
A14: 15 Robertson £12
